<?xml version="1.0"?>
<robot name="jaco"
  xmlns:xi="http://www.w3.org/2001/XInclude"
	xmlns:gazebo="http://playerstage.sourceforge.net/gazebo/xmlschema/#gz"
	xmlns:model="http://playerstage.sourceforge.net/gazebo/xmlschema/#model"
	xmlns:sensor="http://playerstage.sourceforge.net/gazebo/xmlschema/#sensor"
	xmlns:body="http://playerstage.sourceforge.net/gazebo/xmlschema/#body"
	xmlns:geom="http://playerstage.sourceforge.net/gazebo/xmlschema/#geom"
	xmlns:joint="http://playerstage.sourceforge.net/gazebo/xmlschema/#joint"
	xmlns:controller="http://playerstage.sourceforge.net/gazebo/xmlschema/#controller"
	xmlns:interface="http://playerstage.sourceforge.net/gazebo/xmlschema/#interface"
	xmlns:rendering="http://playerstage.sourceforge.net/gazebo/xmlschema/#rendering"
	xmlns:renderable="http://playerstage.sourceforge.net/gazebo/xmlschema/#renderable"
	xmlns:physics="http://playerstage.sourceforge.net/gazebo/xmlschema/#physics"
	xmlns:xacro="http://ros.org/wiki/xacro">
	
  <xacro:property name="M_SCALE" value="0.0254" />
	<xacro:property name="M_PI" value="3.1415926535897931" />
	<xacro:property name="J_LIM" value="${2*M_PI}" />
  
	<xacro:property name="link_base" value="jaco_link_base" />
	<xacro:property name="link" value="jaco_link" />	
	<xacro:property name="link_1" value="jaco_link_1" />
	<xacro:property name="link_2" value="jaco_link_2" />
	<xacro:property name="link_3" value="jaco_link_3" />
	<xacro:property name="link_hand" value="jaco_link_hand" />
	<xacro:property name="link_finger" value="jaco_link_finger" />
	<xacro:property name="link_finger_tip" value="jaco_link_finger_tip" />

	<xacro:property name="joint_base" value="jaco_joint_base" />
	<xacro:property name="joint_base_axis_xyz" value="0 0 0" />

	<xacro:property name="joint_1" value="jaco_joint_1" />
  <xacro:property name="joint_1_axis_xyz" value="0 0 1" />
  <xacro:property name="joint_1_origin_xyz" value="0 0 0.1535" />
  <xacro:property name="joint_1_origin_rpy" value="${M_PI} 0 0" />

  <xacro:property name="joint_2" value="jaco_joint_2" />
  <xacro:property name="joint_2_axis_xyz" value="0 0 1" />
  <xacro:property name="joint_2_origin_xyz" value="0 0 -0.1185" />
  <xacro:property name="joint_2_origin_rpy" value="-${M_PI/2} -${M_PI/2} 0" />

  <xacro:property name="joint_3" value="jaco_joint_3" />
  <xacro:property name="joint_3_axis_xyz" value="0 0 1" />
  <xacro:property name="joint_3_origin_xyz" value="0.41 0 0" />
  <xacro:property name="joint_3_origin_rpy" value="${M_PI} 0 ${M_PI}" />

  <xacro:property name="joint_4" value="jaco_joint_4" />
  <xacro:property name="joint_4_axis_xyz" value="0 0 1" />
  <xacro:property name="joint_4_origin_xyz" value="0.207 0 -0.01125" />
  <xacro:property name="joint_4_origin_rpy" value="0 -${M_PI/2} 0" />

  <xacro:property name="joint_5" value="jaco_joint_5" />
  <xacro:property name="joint_5_axis_xyz" value="0 0 1" />
  <xacro:property name="joint_5_origin_xyz" value="0.0343 0 -0.06588" />
  <xacro:property name="joint_5_origin_rpy" value="0 ${M_PI/180*55} ${M_PI}" />

  <xacro:property name="joint_6" value="jaco_joint_6" />
  <xacro:property name="joint_6_axis_xyz" value="0 0 1" />
  <xacro:property name="joint_6_origin_xyz" value="0.0343 0 -0.06588" />
  <xacro:property name="joint_6_origin_rpy" value="0 ${M_PI/180*55} ${M_PI}" />

  <xacro:property name="joint_finger_1" value="jaco_joint_finger_1" />
  <xacro:property name="joint_finger_1_axis_xyz" value="0 0 1" />
  <xacro:property name="joint_finger_1_origin_xyz" value="-0.032578 0.0033 -0.12131" />  
  <xacro:property name="joint_finger_1_origin_rpy" value="-1.7983 1.117 3.1416" />
  <xacro:property name="joint_finger_1_lower_limit" value="0" />
  <xacro:property name="joint_finger_1_upper_limit" value="${M_PI/180*40}" />

  <xacro:property name="joint_finger_3" value="jaco_joint_finger_3" />
  <xacro:property name="joint_finger_3_axis_xyz" value="0 0 1" />
  <xacro:property name="joint_finger_3_origin_xyz" value="0.027788 -0.0206 -0.12131" />
  <xacro:property name="joint_finger_3_origin_rpy" value="-1.6222 1.117 -0.23615" />
  <xacro:property name="joint_finger_3_lower_limit" value="0" />
  <xacro:property name="joint_finger_3_upper_limit" value="${M_PI/180*40}" />

  <xacro:property name="joint_finger_2" value="jaco_joint_finger_2" />
  <xacro:property name="joint_finger_2_axis_xyz" value="0 0 1" />
  <xacro:property name="joint_finger_2_origin_xyz" value="0.027788 0.0206 -0.12131" />
  <xacro:property name="joint_finger_2_origin_rpy" value="-1.5161 1.1459 0.23978" />
  <xacro:property name="joint_finger_2_lower_limit" value="0" />
  <xacro:property name="joint_finger_2_upper_limit" value="${M_PI/180*40}" />
  
  <xacro:property name="joint_finger_tip_1" value="jaco_joint_finger_tip_1" />
  <xacro:property name="joint_finger_tip_1_axis_xyz" value="0 0 1" />
  <xacro:property name="joint_finger_tip_1_origin_xyz" value="0.044094 -0.0029 0" />  
  <xacro:property name="joint_finger_tip_1_origin_rpy" value="0 0 0" />
  <xacro:property name="joint_finger_tip_1_lower_limit" value="0" />
  <xacro:property name="joint_finger_tip_1_upper_limit" value="${M_PI/180*40}" />
  
  <xacro:property name="joint_finger_tip_2" value="jaco_joint_finger_tip_2" />
  <xacro:property name="joint_finger_tip_2_axis_xyz" value="0 0 1" />
  <xacro:property name="joint_finger_tip_2_origin_xyz" value="0.044094 -0.0029 0" />  
  <xacro:property name="joint_finger_tip_2_origin_rpy" value="0 0 0" />
  <xacro:property name="joint_finger_tip_2_lower_limit" value="0" />
  <xacro:property name="joint_finger_tip_2_upper_limit" value="${M_PI/180*40}" />
  
  <xacro:property name="joint_finger_tip_3" value="jaco_joint_finger_tip_3" />
  <xacro:property name="joint_finger_tip_3_axis_xyz" value="0 0 1" />
  <xacro:property name="joint_finger_tip_3_origin_xyz" value="0.044094 -0.0029 0" />  
  <xacro:property name="joint_finger_tip_3_origin_rpy" value="0 0 0" />
  <xacro:property name="joint_finger_tip_3_lower_limit" value="0" />
  <xacro:property name="joint_finger_tip_3_upper_limit" value="${M_PI/180*40}" />

  <link name="root">
    <visual>
      <origin rpy="0 0 0" xyz="0 0 0"/>
      <geometry>
        <box size="0 0 0"/>
      </geometry>
    </visual>
    <collision>
      <origin rpy="0 0 0" xyz="0 0 0"/>
      <geometry>
        <box size="0 0 0"/>
      </geometry>
    </collision>
  </link>
  <link name="jaco_link_base">
    <inertial>
      <mass value="1.0"/>
      <inertia ixx="0.1" ixy="0" ixz="0" iyy="0.1" iyz="0" izz="0.1"/>
      <origin/>
    </inertial>
    <visual>
      <geometry>
        <mesh filename="package://jaco_description/meshes/jaco_link_base.min.dae" scale="0.0254 0.0254 0.0254"/>
      </geometry>
      <material name="carbon_fiber">
        <color rgba="0.792156862745098 0.819607843137255 0.933333333333333 1"/>
      </material>
    </visual>
    <collision>
      <geometry>
        <mesh filename="package://jaco_description/meshes/jaco_link_base.stl" scale="0.0254 0.0254 0.0254"/>
      </geometry>
    </collision>
  </link>
  <joint name="jaco_joint_base" type="fixed">
    <parent link="root"/>
    <child link="jaco_link_base"/>
    <axis xyz="0 0 1"/>
    <origin rpy="0 0 0" xyz="0 0 0"/>
    <limit effort="30" lower="-6.28318530718" upper="6.28318530718" velocity="5"/>
  </joint>
  <link name="jaco_link_1">
    <inertial>
      <mass value="1.0"/>
      <inertia ixx="0.1" ixy="0" ixz="0" iyy="0.1" iyz="0" izz="0.1"/>
      <origin/>
    </inertial>
    <visual>
      <geometry>
        <mesh filename="package://jaco_description/meshes/jaco_link_1.min.dae" scale="0.0254 0.0254 0.0254"/>
      </geometry>
      <material name="carbon_fiber">
        <color rgba="0.792156862745098 0.819607843137255 0.933333333333333 1"/>
      </material>
    </visual>
    <collision>
      <geometry>
        <mesh filename="package://jaco_description/meshes/jaco_link_1.stl" scale="0.0254 0.0254 0.0254"/>
      </geometry>
    </collision>
  </link>
  <joint name="jaco_joint_1" type="revolute">
    <parent link="jaco_link_base"/>
    <child link="jaco_link_1"/>
    <axis xyz="0 0 1"/>
    <origin rpy="3.14159265359 0 0" xyz="0 0 0.1535"/>
    <limit effort="30" lower="-6.28318530718" upper="6.28318530718" velocity="5"/>
  </joint>
  <transmission name="jaco_joint_1_transmission">
    <type>transmission_interface/SimpleTransmission</type>
    <joint name="jaco_joint_1">
      <hardwareInterface>PositionJointInterface</hardwareInterface>
    </joint>
    <actuator name="jaco_joint_1_motor">
      <mechanicalReduction>1</mechanicalReduction>
    </actuator>
  </transmission>
  <link name="jaco_link_2">
    <inertial>
      <mass value="1.0"/>
      <inertia ixx="0.1" ixy="0" ixz="0" iyy="0.1" iyz="0" izz="0.1"/>
      <origin/>
    </inertial>
    <visual>
      <geometry>
        <mesh filename="package://jaco_description/meshes/jaco_link_2.min.dae" scale="0.0254 0.0254 0.0254"/>
      </geometry>
      <material name="carbon_fiber">
        <color rgba="0.792156862745098 0.819607843137255 0.933333333333333 1"/>
      </material>
    </visual>
    <collision>
      <geometry>
        <mesh filename="package://jaco_description/meshes/jaco_link_2.stl" scale="0.0254 0.0254 0.0254"/>
      </geometry>
    </collision>
  </link>
  <joint name="jaco_joint_2" type="revolute">
    <parent link="jaco_link_1"/>
    <child link="jaco_link_2"/>
    <axis xyz="0 0 1"/>
    <origin rpy="-1.57079632679 -1.57079632679 0" xyz="0 0 -0.1185"/>
    <limit effort="30" lower="0" upper="6.28318530718" velocity="5"/>
  </joint>
  <transmission name="jaco_joint_2_transmission">
    <type>transmission_interface/SimpleTransmission</type>
    <joint name="jaco_joint_2">
      <hardwareInterface>PositionJointInterface</hardwareInterface>
    </joint>
    <actuator name="jaco_joint_2_motor">
      <mechanicalReduction>1</mechanicalReduction>
    </actuator>
  </transmission>
  <link name="jaco_link_3">
    <inertial>
      <mass value="1.0"/>
      <inertia ixx="0.1" ixy="0" ixz="0" iyy="0.1" iyz="0" izz="0.1"/>
      <origin/>
    </inertial>
    <visual>
      <geometry>
        <mesh filename="package://jaco_description/meshes/jaco_link_3.min.dae" scale="0.0254 0.0254 0.0254"/>
      </geometry>
      <material name="carbon_fiber">
        <color rgba="0.792156862745098 0.819607843137255 0.933333333333333 1"/>
      </material>
    </visual>
    <collision>
      <geometry>
        <mesh filename="package://jaco_description/meshes/jaco_link_3.stl" scale="0.0254 0.0254 0.0254"/>
      </geometry>
    </collision>
  </link>
  <joint name="jaco_joint_3" type="revolute">
    <parent link="jaco_link_2"/>
    <child link="jaco_link_3"/>
    <axis xyz="0 0 1"/>
    <origin rpy="3.14159265359 0 3.14159265359" xyz="0.41 0 0"/>
    <limit effort="30" lower="0" upper="6.28318530718" velocity="5"/>
  </joint>
  <transmission name="jaco_joint_3_transmission">
    <type>transmission_interface/SimpleTransmission</type>
    <joint name="jaco_joint_3">
      <hardwareInterface>PositionJointInterface</hardwareInterface>
    </joint>
    <actuator name="jaco_joint_3_motor">
      <mechanicalReduction>1</mechanicalReduction>
    </actuator>
  </transmission>
  <link name="jaco_link_4">
    <inertial>
      <mass value="0.5"/>
      <inertia ixx="0.1" ixy="0" ixz="0" iyy="0.1" iyz="0" izz="0.1"/>
      <origin/>
    </inertial>
    <visual>
      <geometry>
        <mesh filename="package://jaco_description/meshes/jaco_link_4_5.min.dae" scale="0.0254 0.0254 0.0254"/>
      </geometry>
      <material name="carbon_fiber">
        <color rgba="0.792156862745098 0.819607843137255 0.933333333333333 1"/>
      </material>
    </visual>
    <collision>
      <geometry>
        <mesh filename="package://jaco_description/meshes/jaco_link_4_5.stl" scale="0.0254 0.0254 0.0254"/>
      </geometry>
    </collision>
  </link>
  <joint name="jaco_joint_4" type="revolute">
    <parent link="jaco_link_3"/>
    <child link="jaco_link_4"/>
    <axis xyz="0 0 1"/>
    <origin rpy="0 -1.57079632679 0" xyz="0.207 0 -0.01125"/>
    <limit effort="30" lower="-6.28318530718" upper="6.28318530718" velocity="5"/>
  </joint>
  <transmission name="jaco_joint_4_transmission">
    <type>transmission_interface/SimpleTransmission</type>
    <joint name="jaco_joint_4">
      <hardwareInterface>PositionJointInterface</hardwareInterface>
    </joint>
    <actuator name="jaco_joint_4_motor">
      <mechanicalReduction>1</mechanicalReduction>
    </actuator>
  </transmission>
  <link name="jaco_link_5">
    <inertial>
      <mass value="0.5"/>
      <inertia ixx="0.1" ixy="0" ixz="0" iyy="0.1" iyz="0" izz="0.1"/>
      <origin/>
    </inertial>
    <visual>
      <geometry>
        <mesh filename="package://jaco_description/meshes/jaco_link_4_5.min.dae" scale="0.0254 0.0254 0.0254"/>
      </geometry>
      <material name="carbon_fiber">
        <color rgba="0.792156862745098 0.819607843137255 0.933333333333333 1"/>
      </material>
    </visual>
    <collision>
      <geometry>
        <mesh filename="package://jaco_description/meshes/jaco_link_4_5.stl" scale="0.0254 0.0254 0.0254"/>
      </geometry>
    </collision>
  </link>
  <joint name="jaco_joint_5" type="revolute">
    <parent link="jaco_link_4"/>
    <child link="jaco_link_5"/>
    <axis xyz="0 0 1"/>
    <origin rpy="0 0.959931088597 3.14159265359" xyz="0.0343 0 -0.06588"/>
    <limit effort="30" lower="-6.28318530718" upper="6.28318530718" velocity="5"/>
  </joint>
  <transmission name="jaco_joint_5_transmission">
    <type>transmission_interface/SimpleTransmission</type>
    <joint name="jaco_joint_5">
      <hardwareInterface>PositionJointInterface</hardwareInterface>
    </joint>
    <actuator name="jaco_joint_5_motor">
      <mechanicalReduction>1</mechanicalReduction>
    </actuator>
  </transmission>
  <link name="jaco_link_hand">
    <inertial>
      <mass value="1.0"/>
      <inertia ixx="0.1" ixy="0" ixz="0" iyy="0.1" iyz="0" izz="0.1"/>
      <origin/>
    </inertial>
    <visual>
      <geometry>
        <mesh filename="package://jaco_description/meshes/jaco_link_hand.min.dae" scale="0.0254 0.0254 0.0254"/>
      </geometry>
      <material name="carbon_fiber">
        <color rgba="0.792156862745098 0.819607843137255 0.933333333333333 1"/>
      </material>
    </visual>
    <collision>
      <geometry>
        <mesh filename="package://jaco_description/meshes/jaco_link_hand.stl" scale="0.0254 0.0254 0.0254"/>
      </geometry>
    </collision>
  </link>
  <joint name="jaco_joint_6" type="revolute">
    <parent link="jaco_link_5"/>
    <child link="jaco_link_hand"/>
    <axis xyz="0 0 1"/>
    <origin rpy="0 0.959931088597 3.14159265359" xyz="0.0343 0 -0.06588"/>
    <limit effort="30" lower="-6.28318530718" upper="6.28318530718" velocity="5"/>
  </joint>
  <transmission name="jaco_joint_6_transmission">
    <type>transmission_interface/SimpleTransmission</type>
    <joint name="jaco_joint_6">
      <hardwareInterface>PositionJointInterface</hardwareInterface>
    </joint>
    <actuator name="jaco_joint_6_motor">
      <mechanicalReduction>1</mechanicalReduction>
    </actuator>
  </transmission>
  <link name="jaco_large_ring_cover_1">
    <inertial>
      <mass value="0.001"/>
      <inertia ixx="0.1" ixy="0" ixz="0" iyy="0.1" iyz="0" izz="0.1"/>
      <origin/>
    </inertial>
    <visual>
      <geometry>
        <mesh filename="package://jaco_description/meshes/jaco_large_ring_cover.min.dae" scale="0.0254 0.0254 0.0254"/>
      </geometry>
      <material name="carbon_fiber">
        <color rgba="0.792156862745098 0.819607843137255 0.933333333333333 1"/>
      </material>
    </visual>
    <collision>
      <geometry>
        <mesh filename="package://jaco_description/meshes/jaco_large_ring_cover.stl" scale="0.0254 0.0254 0.0254"/>
      </geometry>
    </collision>
  </link>
  <joint name="jaco_large_ring_cover_1_joint" type="fixed">
    <parent link="jaco_link_base"/>
    <child link="jaco_large_ring_cover_1"/>
    <axis xyz="0 0 1"/>
    <origin rpy="3.14159265359 0 0" xyz="0 0 0.1535"/>
    <limit effort="30" lower="-6.28318530718" upper="6.28318530718" velocity="5"/>
  </joint>
  <link name="jaco_large_ring_cover_2">
    <inertial>
      <mass value="0.001"/>
      <inertia ixx="0.1" ixy="0" ixz="0" iyy="0.1" iyz="0" izz="0.1"/>
      <origin/>
    </inertial>
    <visual>
      <geometry>
        <mesh filename="package://jaco_description/meshes/jaco_large_ring_cover.min.dae" scale="0.0254 0.0254 0.0254"/>
      </geometry>
      <material name="carbon_fiber">
        <color rgba="0.792156862745098 0.819607843137255 0.933333333333333 1"/>
      </material>
    </visual>
    <collision>
      <geometry>
        <mesh filename="package://jaco_description/meshes/jaco_large_ring_cover.stl" scale="0.0254 0.0254 0.0254"/>
      </geometry>
    </collision>
  </link>
  <joint name="jaco_large_ring_cover_2_joint" type="fixed">
    <parent link="jaco_link_1"/>
    <child link="jaco_large_ring_cover_2"/>
    <axis xyz="0 0 1"/>
    <origin rpy="-1.57079632679 -1.57079632679 0" xyz="0 0 -0.1185"/>
    <limit effort="30" lower="0" upper="6.28318530718" velocity="5"/>
  </joint>
  <link name="jaco_large_ring_cover_3">
    <inertial>
      <mass value="0.001"/>
      <inertia ixx="0.1" ixy="0" ixz="0" iyy="0.1" iyz="0" izz="0.1"/>
      <origin/>
    </inertial>
    <visual>
      <geometry>
        <mesh filename="package://jaco_description/meshes/jaco_large_ring_cover.min.dae" scale="0.0254 0.0254 0.0254"/>
      </geometry>
      <material name="carbon_fiber">
        <color rgba="0.792156862745098 0.819607843137255 0.933333333333333 1"/>
      </material>
    </visual>
    <collision>
      <geometry>
        <mesh filename="package://jaco_description/meshes/jaco_large_ring_cover.stl" scale="0.0254 0.0254 0.0254"/>
      </geometry>
    </collision>
  </link>
  <joint name="jaco_large_ring_cover_3_joint" type="fixed">
    <parent link="jaco_link_2"/>
    <child link="jaco_large_ring_cover_3"/>
    <axis xyz="0 0 1"/>
    <origin rpy="3.14159265359 0 3.14159265359" xyz="0.41 0 0"/>
    <limit effort="30" lower="0" upper="6.28318530718" velocity="5"/>
  </joint>
  <link name="jaco_small_ring_cover_1">
    <inertial>
      <mass value="0.001"/>
      <inertia ixx="0.1" ixy="0" ixz="0" iyy="0.1" iyz="0" izz="0.1"/>
      <origin/>
    </inertial>
    <visual>
      <geometry>
        <mesh filename="package://jaco_description/meshes/jaco_small_ring_cover.min.dae" scale="0.0254 0.0254 0.0254"/>
      </geometry>
      <material name="carbon_fiber">
        <color rgba="0.792156862745098 0.819607843137255 0.933333333333333 1"/>
      </material>
    </visual>
    <collision>
      <geometry>
        <mesh filename="package://jaco_description/meshes/jaco_small_ring_cover.stl" scale="0.0254 0.0254 0.0254"/>
      </geometry>
    </collision>
  </link>
  <joint name="jaco_large_ring_cover_4_joint" type="fixed">
    <parent link="jaco_link_3"/>
    <child link="jaco_small_ring_cover_1"/>
    <axis xyz="0 0 1"/>
    <origin rpy="0 -1.57079632679 0" xyz="0.207 0 -0.01125"/>
    <limit effort="30" lower="-6.28318530718" upper="6.28318530718" velocity="5"/>
  </joint>
  <link name="jaco_small_ring_cover_2">
    <inertial>
      <mass value="0.001"/>
      <inertia ixx="0.1" ixy="0" ixz="0" iyy="0.1" iyz="0" izz="0.1"/>
      <origin/>
    </inertial>
    <visual>
      <geometry>
        <mesh filename="package://jaco_description/meshes/jaco_small_ring_cover.min.dae" scale="0.0254 0.0254 0.0254"/>
      </geometry>
      <material name="carbon_fiber">
        <color rgba="0.792156862745098 0.819607843137255 0.933333333333333 1"/>
      </material>
    </visual>
    <collision>
      <geometry>
        <mesh filename="package://jaco_description/meshes/jaco_small_ring_cover.stl" scale="0.0254 0.0254 0.0254"/>
      </geometry>
    </collision>
  </link>
  <joint name="jaco_large_ring_cover_5_joint" type="fixed">
    <parent link="jaco_link_4"/>
    <child link="jaco_small_ring_cover_2"/>
    <axis xyz="0 0 1"/>
    <origin rpy="0 0.959931088597 3.14159265359" xyz="0.0343 0 -0.06588"/>
    <limit effort="30" lower="-6.28318530718" upper="6.28318530718" velocity="5"/>
  </joint>
  <link name="jaco_small_ring_cover_3">
    <inertial>
      <mass value="0.001"/>
      <inertia ixx="0.1" ixy="0" ixz="0" iyy="0.1" iyz="0" izz="0.1"/>
      <origin/>
    </inertial>
    <visual>
      <geometry>
        <mesh filename="package://jaco_description/meshes/jaco_small_ring_cover.min.dae" scale="0.0254 0.0254 0.0254"/>
      </geometry>
      <material name="carbon_fiber">
        <color rgba="0.792156862745098 0.819607843137255 0.933333333333333 1"/>
      </material>
    </visual>
    <collision>
      <geometry>
        <mesh filename="package://jaco_description/meshes/jaco_small_ring_cover.stl" scale="0.0254 0.0254 0.0254"/>
      </geometry>
    </collision>
  </link>
  <joint name="jaco_large_ring_cover_6_joint" type="fixed">
    <parent link="jaco_link_5"/>
    <child link="jaco_small_ring_cover_3"/>
    <axis xyz="0 0 1"/>
    <origin rpy="0 0.959931088597 3.14159265359" xyz="0.0343 0 -0.06588"/>
    <limit effort="30" lower="-6.28318530718" upper="6.28318530718" velocity="5"/>
  </joint>
  <link name="jaco_link_finger_1">
    <inertial>
      <mass value="0.25"/>
      <inertia ixx="0.1" ixy="0" ixz="0" iyy="0.1" iyz="0" izz="0.1"/>
      <origin/>
    </inertial>
    <visual>
      <geometry>
        <mesh filename="package://jaco_description/meshes/jaco_link_finger.min.dae" scale="0.0254 0.0254 0.0254"/>
      </geometry>
      <material name="carbon_fiber">
        <color rgba="0.792156862745098 0.819607843137255 0.933333333333333 1"/>
      </material>
    </visual>
    <collision>
      <geometry>
        <mesh filename="package://jaco_description/meshes/jaco_link_finger.stl" scale="0.0254 0.0254 0.0254"/>
      </geometry>
    </collision>
  </link>
  <joint name="jaco_joint_finger_1" type="revolute">
    <parent link="jaco_link_hand"/>
    <child link="jaco_link_finger_1"/>
    <axis xyz="0 0 1"/>
    <origin rpy="-1.7983 1.117 3.1416" xyz="-0.032578 0.0033 -0.12131"/>
    <limit effort="30" lower="0" upper="0.698131700798" velocity="5"/>
  </joint>
  <transmission name="jaco_joint_finger_1_transmission">
    <type>transmission_interface/SimpleTransmission</type>
    <joint name="jaco_joint_finger_1">
      <hardwareInterface>PositionJointInterface</hardwareInterface>
    </joint>
    <actuator name="jaco_joint_finger_1_motor">
      <mechanicalReduction>1</mechanicalReduction>
    </actuator>
  </transmission>
  <link name="jaco_link_finger_2">
    <inertial>
      <mass value="0.25"/>
      <inertia ixx="0.1" ixy="0" ixz="0" iyy="0.1" iyz="0" izz="0.1"/>
      <origin/>
    </inertial>
    <visual>
      <geometry>
        <mesh filename="package://jaco_description/meshes/jaco_link_finger.min.dae" scale="0.0254 0.0254 0.0254"/>
      </geometry>
      <material name="carbon_fiber">
        <color rgba="0.792156862745098 0.819607843137255 0.933333333333333 1"/>
      </material>
    </visual>
    <collision>
      <geometry>
        <mesh filename="package://jaco_description/meshes/jaco_link_finger.stl" scale="0.0254 0.0254 0.0254"/>
      </geometry>
    </collision>
  </link>
  <joint name="jaco_joint_finger_2" type="revolute">
    <parent link="jaco_link_hand"/>
    <child link="jaco_link_finger_2"/>
    <axis xyz="0 0 1"/>
    <origin rpy="-1.5161 1.1459 0.23978" xyz="0.027788 0.0206 -0.12131"/>
    <limit effort="30" lower="0" upper="0.698131700798" velocity="5"/>
  </joint>
  <transmission name="jaco_joint_finger_2_transmission">
    <type>transmission_interface/SimpleTransmission</type>
    <joint name="jaco_joint_finger_2">
      <hardwareInterface>PositionJointInterface</hardwareInterface>
    </joint>
    <actuator name="jaco_joint_finger_2_motor">
      <mechanicalReduction>1</mechanicalReduction>
    </actuator>
  </transmission>
  <link name="jaco_link_finger_3">
    <inertial>
      <mass value="0.25"/>
      <inertia ixx="0.1" ixy="0" ixz="0" iyy="0.1" iyz="0" izz="0.1"/>
      <origin/>
    </inertial>
    <visual>
      <geometry>
        <mesh filename="package://jaco_description/meshes/jaco_link_finger.min.dae" scale="0.0254 0.0254 0.0254"/>
      </geometry>
      <material name="carbon_fiber">
        <color rgba="0.792156862745098 0.819607843137255 0.933333333333333 1"/>
      </material>
    </visual>
    <collision>
      <geometry>
        <mesh filename="package://jaco_description/meshes/jaco_link_finger.stl" scale="0.0254 0.0254 0.0254"/>
      </geometry>
    </collision>
  </link>
  <joint name="jaco_joint_finger_3" type="revolute">
    <parent link="jaco_link_hand"/>
    <child link="jaco_link_finger_3"/>
    <axis xyz="0 0 1"/>
    <origin rpy="-1.6222 1.117 -0.23615" xyz="0.027788 -0.0206 -0.12131"/>
    <limit effort="30" lower="0" upper="0.698131700798" velocity="5"/>
  </joint>
  <transmission name="jaco_joint_finger_3_transmission">
    <type>transmission_interface/SimpleTransmission</type>
    <joint name="jaco_joint_finger_3">
      <hardwareInterface>PositionJointInterface</hardwareInterface>
    </joint>
    <actuator name="jaco_joint_finger_3_motor">
      <mechanicalReduction>1</mechanicalReduction>
    </actuator>
  </transmission>
  <link name="jaco_link_finger_tip_1">
    <inertial>
      <mass value="0.25"/>
      <inertia ixx="0.1" ixy="0" ixz="0" iyy="0.1" iyz="0" izz="0.1"/>
      <origin/>
    </inertial>
    <visual>
      <geometry>
        <mesh filename="package://jaco_description/meshes/jaco_link_finger_tip.min.dae" scale="0.0254 0.0254 0.0254"/>
      </geometry>
      <material name="carbon_fiber">
        <color rgba="0.792156862745098 0.819607843137255 0.933333333333333 1"/>
      </material>
    </visual>
    <collision>
      <geometry>
        <mesh filename="package://jaco_description/meshes/jaco_link_finger_tip.stl" scale="0.0254 0.0254 0.0254"/>
      </geometry>
    </collision>
  </link>
  <joint name="jaco_joint_finger_tip_1" type="revolute">
    <parent link="jaco_link_finger_1"/>
    <child link="jaco_link_finger_tip_1"/>
    <axis xyz="0 0 1"/>
    <origin rpy="0 0 0" xyz="0.044094 -0.0029 0"/>
    <limit effort="30" lower="0" upper="0.698131700798" velocity="5"/>
  </joint>
  <transmission name="jaco_joint_finger_tip_1_transmission">
    <type>transmission_interface/SimpleTransmission</type>
    <joint name="jaco_joint_finger_tip_1">
      <hardwareInterface>PositionJointInterface</hardwareInterface>
    </joint>
    <actuator name="jaco_joint_finger_tip_1_motor">
      <mechanicalReduction>1</mechanicalReduction>
    </actuator>
  </transmission>
  <link name="jaco_link_finger_tip_2">
    <inertial>
      <mass value="0.25"/>
      <inertia ixx="0.1" ixy="0" ixz="0" iyy="0.1" iyz="0" izz="0.1"/>
      <origin/>
    </inertial>
    <visual>
      <geometry>
        <mesh filename="package://jaco_description/meshes/jaco_link_finger_tip.min.dae" scale="0.0254 0.0254 0.0254"/>
      </geometry>
      <material name="carbon_fiber">
        <color rgba="0.792156862745098 0.819607843137255 0.933333333333333 1"/>
      </material>
    </visual>
    <collision>
      <geometry>
        <mesh filename="package://jaco_description/meshes/jaco_link_finger_tip.stl" scale="0.0254 0.0254 0.0254"/>
      </geometry>
    </collision>
  </link>
  <joint name="jaco_joint_finger_tip_2" type="revolute">
    <parent link="jaco_link_finger_2"/>
    <child link="jaco_link_finger_tip_2"/>
    <axis xyz="0 0 1"/>
    <origin rpy="0 0 0" xyz="0.044094 -0.0029 0"/>
    <limit effort="30" lower="0" upper="0.698131700798" velocity="5"/>
  </joint>
  <transmission name="jaco_joint_finger_tip_2_transmission">
    <type>transmission_interface/SimpleTransmission</type>
    <joint name="jaco_joint_finger_tip_2">
      <hardwareInterface>PositionJointInterface</hardwareInterface>
    </joint>
    <actuator name="jaco_joint_finger_tip_2_motor">
      <mechanicalReduction>1</mechanicalReduction>
    </actuator>
  </transmission>
  <link name="jaco_link_finger_tip_3">
    <inertial>
      <mass value="0.25"/>
      <inertia ixx="0.1" ixy="0" ixz="0" iyy="0.1" iyz="0" izz="0.1"/>
      <origin/>
    </inertial>
    <visual>
      <geometry>
        <mesh filename="package://jaco_description/meshes/jaco_link_finger_tip.min.dae" scale="0.0254 0.0254 0.0254"/>
      </geometry>
      <material name="carbon_fiber">
        <color rgba="0.792156862745098 0.819607843137255 0.933333333333333 1"/>
      </material>
    </visual>
    <collision>
      <geometry>
        <mesh filename="package://jaco_description/meshes/jaco_link_finger_tip.stl" scale="0.0254 0.0254 0.0254"/>
      </geometry>
    </collision>
  </link>
  <joint name="jaco_joint_finger_tip_3" type="revolute">
    <parent link="jaco_link_finger_3"/>
    <child link="jaco_link_finger_tip_3"/>
    <axis xyz="0 0 1"/>
    <origin rpy="0 0 0" xyz="0.044094 -0.0029 0"/>
    <limit effort="30" lower="0" upper="0.698131700798" velocity="5"/>
  </joint>

	<xacro:macro name="jaco_transmission" params="joint_name">
        <transmission name="${joint_name}_transmission">
            <type>transmission_interface/SimpleTransmission</type>
            <joint name="${joint_name}">
              <hardwareInterface>PositionJointInterface</hardwareInterface>
            </joint>
            <actuator name="${joint_name}_motor">
              <mechanicalReduction>1</mechanicalReduction>
            </actuator>
        </transmission>
	</xacro:macro>
    
	<xacro:macro name="jaco" params="parent xyz rpy simple_collisions:=0 gazebo_robot_name:=robot_description">
        <gazebo>
            <plugin filename="libgazebo_ros_control.so" name="gazebo_ros_controller_manager">
                <!-- <robotNamespace>/</robotNamespace> -->
		<robotParam>${gazebo_robot_name}</robotParam>
            </plugin>
        </gazebo>
      
		<xacro:jaco_link_with_collisions link_name="${link_base}" simple_collisions="${simple_collisions}"><xacro:insert_block name="link_base_link_data" /></xacro:jaco_link_with_collisions>
		<xacro:jaco_joint joint_name="${joint_base}" type="fixed" parent="${parent}" child="${link_base}" joint_axis_xyz="${joint_base_axis_xyz}" joint_origin_xyz="${xyz}" joint_origin_rpy="${rpy}" lower_limit="-${J_LIM}" upper_limit="${J_LIM}" />
        
		<xacro:jaco_link_with_collisions link_name="${link_1}" simple_collisions="${simple_collisions}"><xacro:insert_block name="link_1_link_data" /></xacro:jaco_link_with_collisions>
		<xacro:jaco_joint joint_name="${joint_1}" type="revolute" parent="${link_base}" child="${link_1}" joint_axis_xyz="${joint_1_axis_xyz}" joint_origin_xyz="${joint_1_origin_xyz}" joint_origin_rpy="${joint_1_origin_rpy}" lower_limit="-${J_LIM}" upper_limit="${J_LIM}" />
        <xacro:jaco_transmission joint_name="${joint_1}" />
        
		<xacro:jaco_link_with_collisions link_name="${link_2}" simple_collisions="${simple_collisions}"><xacro:insert_block name="link_2_link_data" /></xacro:jaco_link_with_collisions>
		<xacro:jaco_joint joint_name="${joint_2}" type="revolute" parent="${link_1}" child="${link_2}" joint_axis_xyz="${joint_2_axis_xyz}" joint_origin_xyz="${joint_2_origin_xyz}" joint_origin_rpy="${joint_2_origin_rpy}" lower_limit="0" upper_limit="${J_LIM}" />
        <xacro:jaco_transmission joint_name="${joint_2}" />
        
		<xacro:jaco_link_with_collisions link_name="${link_3}" simple_collisions="${simple_collisions}"><xacro:insert_block name="link_3_link_data" /></xacro:jaco_link_with_collisions>
		<xacro:jaco_joint joint_name="${joint_3}" type="revolute" parent="${link_2}" child="${link_3}" joint_axis_xyz="${joint_3_axis_xyz}" joint_origin_xyz="${joint_3_origin_xyz}" joint_origin_rpy="${joint_3_origin_rpy}" lower_limit="0" upper_limit="${J_LIM}" />
        <xacro:jaco_transmission joint_name="${joint_3}" />

		<xacro:jaco_link_with_collisions mass="0.5" link_name="${link}" suffix="4" suffix_separator="_" file_suffix="_4_5" simple_collisions="${simple_collisions}"><xacro:insert_block name="link_4_5_link_data" /></xacro:jaco_link_with_collisions>
		<xacro:jaco_joint joint_name="${joint_4}" type="revolute" parent="${link_3}" child="${link}_4" joint_axis_xyz="${joint_4_axis_xyz}" joint_origin_xyz="${joint_4_origin_xyz}" joint_origin_rpy="${joint_4_origin_rpy}" lower_limit="-${J_LIM}" upper_limit="${J_LIM}" />
        <xacro:jaco_transmission joint_name="${joint_4}" />
        
		<xacro:jaco_link_with_collisions mass="0.5" link_name="${link}" suffix="5" suffix_separator="_" file_suffix="_4_5" simple_collisions="${simple_collisions}"><xacro:insert_block name="link_4_5_link_data" /></xacro:jaco_link_with_collisions>
		<xacro:jaco_joint joint_name="${joint_5}" type="revolute" parent="${link}_4" child="${link}_5" joint_axis_xyz="${joint_5_axis_xyz}" joint_origin_xyz="${joint_5_origin_xyz}" joint_origin_rpy="${joint_5_origin_rpy}" lower_limit="-${J_LIM}" upper_limit="${J_LIM}" />
        <xacro:jaco_transmission joint_name="${joint_5}" />
        
		<xacro:jaco_link_with_collisions link_name="${link_hand}" simple_collisions="${simple_collisions}"><xacro:insert_block name="link_hand_link_data" /></xacro:jaco_link_with_collisions>
		<xacro:jaco_joint joint_name="${joint_6}" type="revolute" parent="${link}_5" child="${link_hand}" joint_axis_xyz="${joint_6_axis_xyz}" joint_origin_xyz="${joint_6_origin_xyz}" joint_origin_rpy="${joint_6_origin_rpy}" lower_limit="-${J_LIM}" upper_limit="${J_LIM}" />
        <xacro:jaco_transmission joint_name="${joint_6}" />
				
		<xacro:jaco_link_with_collisions mass="0.001" link_name="jaco_large_ring_cover" suffix="1" suffix_separator="_" simple_collisions="${simple_collisions}"><xacro:insert_block name="large_ring_data" /></xacro:jaco_link_with_collisions>
		<xacro:jaco_joint joint_name="jaco_large_ring_cover_1_joint" type="fixed" parent="${link_base}" child="jaco_large_ring_cover_1" joint_axis_xyz="${joint_1_axis_xyz}" joint_origin_xyz="${joint_1_origin_xyz}" joint_origin_rpy="${joint_1_origin_rpy}" lower_limit="-${J_LIM}" upper_limit="${J_LIM}" />
		<xacro:jaco_link_with_collisions mass="0.001" link_name="jaco_large_ring_cover" suffix="2" suffix_separator="_" simple_collisions="${simple_collisions}"><xacro:insert_block name="large_ring_data" /></xacro:jaco_link_with_collisions>
		<xacro:jaco_joint joint_name="jaco_large_ring_cover_2_joint" type="fixed" parent="${link_1}" child="jaco_large_ring_cover_2" joint_axis_xyz="${joint_2_axis_xyz}" joint_origin_xyz="${joint_2_origin_xyz}" joint_origin_rpy="${joint_2_origin_rpy}" lower_limit="0" upper_limit="${J_LIM}" />
		<xacro:jaco_link_with_collisions mass="0.001" link_name="jaco_large_ring_cover" suffix="3" suffix_separator="_" simple_collisions="${simple_collisions}"><xacro:insert_block name="large_ring_data" /></xacro:jaco_link_with_collisions>
		<xacro:jaco_joint joint_name="jaco_large_ring_cover_3_joint" type="fixed" parent="${link_2}" child="jaco_large_ring_cover_3" joint_axis_xyz="${joint_3_axis_xyz}" joint_origin_xyz="${joint_3_origin_xyz}" joint_origin_rpy="${joint_3_origin_rpy}" lower_limit="0" upper_limit="${J_LIM}" />
		<xacro:jaco_link_with_collisions mass="0.001" link_name="jaco_small_ring_cover" suffix="1" suffix_separator="_" simple_collisions="${simple_collisions}"><xacro:insert_block name="small_ring_data" /></xacro:jaco_link_with_collisions>
		<xacro:jaco_joint joint_name="jaco_large_ring_cover_4_joint" type="fixed" parent="${link_3}" child="jaco_small_ring_cover_1" joint_axis_xyz="${joint_4_axis_xyz}" joint_origin_xyz="${joint_4_origin_xyz}" joint_origin_rpy="${joint_4_origin_rpy}" lower_limit="-${J_LIM}" upper_limit="${J_LIM}" />
		<xacro:jaco_link_with_collisions mass="0.001" link_name="jaco_small_ring_cover" suffix="2" suffix_separator="_" simple_collisions="${simple_collisions}"><xacro:insert_block name="small_ring_data" /></xacro:jaco_link_with_collisions>
		<xacro:jaco_joint joint_name="jaco_large_ring_cover_5_joint" type="fixed" parent="${link}_4" child="jaco_small_ring_cover_2" joint_axis_xyz="${joint_5_axis_xyz}" joint_origin_xyz="${joint_5_origin_xyz}" joint_origin_rpy="${joint_5_origin_rpy}" lower_limit="-${J_LIM}" upper_limit="${J_LIM}" />
		<xacro:jaco_link_with_collisions mass="0.001" link_name="jaco_small_ring_cover" suffix="3" suffix_separator="_" simple_collisions="${simple_collisions}"><xacro:insert_block name="small_ring_data" /></xacro:jaco_link_with_collisions>
		<xacro:jaco_joint joint_name="jaco_large_ring_cover_6_joint" type="fixed" parent="${link}_5" child="jaco_small_ring_cover_3" joint_axis_xyz="${joint_6_axis_xyz}" joint_origin_xyz="${joint_6_origin_xyz}" joint_origin_rpy="${joint_6_origin_rpy}" lower_limit="-${J_LIM}" upper_limit="${J_LIM}" />

		<xacro:jaco_link_with_collisions mass="0.25" link_name="${link_finger}" suffix="1" suffix_separator="_" simple_collisions="${simple_collisions}"><xacro:insert_block name="finger_link_data" /></xacro:jaco_link_with_collisions>
		<xacro:jaco_finger_joint joint_name="${joint_finger_1}" type="revolute" parent="${link_hand}" child="${link_finger}_1" joint_axis_xyz="${joint_finger_1_axis_xyz}" joint_origin_xyz="${joint_finger_1_origin_xyz}" joint_origin_rpy="${joint_finger_1_origin_rpy}" lower_limit="${joint_finger_1_lower_limit}" upper_limit="${joint_finger_1_upper_limit}" />
        <xacro:jaco_transmission joint_name="${joint_finger_1}" />
        
		<xacro:jaco_link_with_collisions mass="0.25" link_name="${link_finger}" suffix="2" suffix_separator="_" simple_collisions="${simple_collisions}"><xacro:insert_block name="finger_link_data" /></xacro:jaco_link_with_collisions>
		<xacro:jaco_finger_joint joint_name="${joint_finger_2}" type="revolute" parent="${link_hand}" child="${link_finger}_2" joint_axis_xyz="${joint_finger_2_axis_xyz}" joint_origin_xyz="${joint_finger_2_origin_xyz}" joint_origin_rpy="${joint_finger_2_origin_rpy}" lower_limit="${joint_finger_2_lower_limit}" upper_limit="${joint_finger_2_upper_limit}" />
        <xacro:jaco_transmission joint_name="${joint_finger_2}" />
        
		<xacro:jaco_link_with_collisions mass="0.25" link_name="${link_finger}" suffix="3" suffix_separator="_" simple_collisions="${simple_collisions}"><xacro:insert_block name="finger_link_data" /></xacro:jaco_link_with_collisions>
		<xacro:jaco_finger_joint joint_name="${joint_finger_3}" type="revolute" parent="${link_hand}" child="${link_finger}_3" joint_axis_xyz="${joint_finger_3_axis_xyz}" joint_origin_xyz="${joint_finger_3_origin_xyz}" joint_origin_rpy="${joint_finger_3_origin_rpy}" lower_limit="${joint_finger_3_lower_limit}" upper_limit="${joint_finger_3_upper_limit}" />	
        <xacro:jaco_transmission joint_name="${joint_finger_3}" />
        
		<xacro:jaco_link_with_collisions mass="0.25" link_name="${link_finger_tip}" suffix="1" suffix_separator="_" simple_collisions="${simple_collisions}"><xacro:insert_block name="finger_tip_link_data" /></xacro:jaco_link_with_collisions>
		<xacro:jaco_finger_joint joint_name="${joint_finger_tip_1}" type="revolute" parent="${link_finger}_1" child="${link_finger_tip}_1" joint_axis_xyz="${joint_finger_tip_1_axis_xyz}" joint_origin_xyz="${joint_finger_tip_1_origin_xyz}" joint_origin_rpy="${joint_finger_tip_1_origin_rpy}" lower_limit="${joint_finger_tip_1_lower_limit}" upper_limit="${joint_finger_tip_1_upper_limit}" />
        <xacro:jaco_transmission joint_name="${joint_finger_tip_1}" />
        
		<xacro:jaco_link_with_collisions mass="0.25" link_name="${link_finger_tip}" suffix="2" suffix_separator="_" simple_collisions="${simple_collisions}"><xacro:insert_block name="finger_tip_link_data" /></xacro:jaco_link_with_collisions>
		<xacro:jaco_finger_joint joint_name="${joint_finger_tip_2}" type="revolute" parent="${link_finger}_2" child="${link_finger_tip}_2" joint_axis_xyz="${joint_finger_tip_2_axis_xyz}" joint_origin_xyz="${joint_finger_tip_2_origin_xyz}" joint_origin_rpy="${joint_finger_tip_2_origin_rpy}" lower_limit="${joint_finger_tip_2_lower_limit}" upper_limit="${joint_finger_tip_2_upper_limit}" />
        <xacro:jaco_transmission joint_name="${joint_finger_tip_2}" />
        
		<xacro:jaco_link_with_collisions mass="0.25" link_name="${link_finger_tip}" suffix="3" suffix_separator="_" simple_collisions="${simple_collisions}"><xacro:insert_block name="finger_tip_link_data" /></xacro:jaco_link_with_collisions>
		<xacro:jaco_finger_joint joint_name="${joint_finger_tip_3}" type="revolute" parent="${link_finger}_3" child="${link_finger_tip}_3" joint_axis_xyz="${joint_finger_tip_3_axis_xyz}" joint_origin_xyz="${joint_finger_tip_3_origin_xyz}" joint_origin_rpy="${joint_finger_tip_3_origin_rpy}" lower_limit="${joint_finger_tip_3_lower_limit}" upper_limit="${joint_finger_tip_3_upper_limit}" />
        <xacro:jaco_transmission joint_name="${joint_finger_tip_3}" />

        <gazebo>
          <gripper name="grasping">
            <grasp_check>
              <attach_steps>5</attach_steps>
              <detach_steps>5</detach_steps>
              <min_contact_count>1</min_contact_count>
            </grasp_check>
            <gripper_link>${link_finger}_1</gripper_link>
            <gripper_link>${link_finger}_2</gripper_link>
            <gripper_link>${link_finger}_3</gripper_link>
            <gripper_link>${link_finger_tip}_1</gripper_link>
            <gripper_link>${link_finger_tip}_2</gripper_link>
            <gripper_link>${link_finger_tip}_3</gripper_link>
            <palm_link>${link_hand}</palm_link>
            <!-- <gripper_link>${link_hand}</gripper_link> -->
            <!-- <palm_link>${link_finger_tip}_1</palm_link> -->
          </gripper>
        </gazebo>
	</xacro:macro>
  
  <xacro:include filename="$(find jaco_description)/urdf/plugin_joint_control.urdf.xacro"/>
  <xacro:plugin_joint_control robot_components_namespace="jaco"
                              trajectory_param_namespace="jaco_trajector"/>
</robot>
